Workbook

Sheet BIMBO
B1: BIMBOA.MX | C1: R_BIMBO | E1: Rendimiento | F1: =AVERAGE(C3:C1260) -> 0.0005193885
A2: 0 | B2: 33.610001 | E2: Varianza | F2: =_xlfn.VAR.S(C:C) -> 0.00046028742
A3: 1 | B3: 33.919998 | C3: =+LN(B3/B2) -> 0.009181097 | E3: Volatilidad | F3: =SQRT(F2) -> 0.02145431
A4: 2 | B4: 35.889999 | C4: =LN(B4/B3) -> 0.056453931
A5: 3 | B5: 36.049999 | C5: =LN(B5/B4) -> 0.0044481544
A6: 4 | B6: 36.950001 | C6: =LN(B6/B5) -> 0.024658825
A7: 5 | B7: 36.959999 | C7: =LN(B7/B6) -> 0.00027055396
A8: 6 | B8: 35.740002 | C8: =LN(B8/B7) -> -0.033565665
A9: 7 | B9: 36.41 | C9: =LN(B9/B8) -> 0.018572901
A10: 8 | B10: 36.540001 | C10: =LN(B10/B9) -> 0.003564118
A11: 9 | B11: 36.889999 | C11: =LN(B11/B10) -> 0.0095329191
A12: 10 | B12: 36.189999 | C12: =LN(B12/B11) -> -0.019157695
A13: 11 | B13: 36.720001 | C13: =LN(B13/B12) -> 0.014538799
A14: 12 | B14: 35.869999 | C14: =LN(B14/B13) -> -0.023420337
A15: 13 | B15: 36.540001 | C15: =LN(B15/B14) -> 0.018506314
... A1260: 1258 | B1260: 64.599998 | C1260: =LN(B1260/B1259) -> -0.00092844177

Sheet GrupoCarso
B1: GCARSOA1.MX | C1: R_GCarso | E1: Rendimiento | F1: =AVERAGE(C:C) -> 0.00050333563
A2: 0 | B2: 63.07 | E2: Varianza | F2: =_xlfn.VAR.S(C:C) -> 0.00061694381
A3: 1 | B3: 62.139999 | C3: =LN(B3/B2) -> -0.014855322 | E3: Volatilidad | F3: =SQRT(F2) -> 0.024838354
A4: 2 | B4: 61.509998 | C4: =LN(B4/B3) -> -0.010190158
A5: 3 | B5: 64.720001 | C5: =LN(B5/B4) -> 0.050870556
A6: 4 | B6: 66.550003 | C6: =LN(B6/B5) -> 0.027883299
A7: 5 | B7: 66.269997 | C7: =LN(B7/B6) -> -0.0042163353
A8: 6 | B8: 64.400002 | C8: =LN(B8/B7) -> -0.028623599
A9: 7 | B9: 68.120003 | C9: =LN(B9/B8) -> 0.056157239
A10: 8 | B10: 66.919998 | C10: =LN(B10/B9) -> -0.017773047
A11: 9 | B11: 67.980003 | C11: =LN(B11/B10) -> 0.015715745
A12: 10 | B12: 68.110001 | C12: =LN(B12/B11) -> 0.0019104606
A13: 11 | B13: 69.139999 | C13: =LN(B13/B12) -> 0.015009371
A14: 12 | B14: 67.220001 | C14: =LN(B14/B13) -> -0.028162585
A15: 13 | B15: 68.370003 | C15: =LN(B15/B14) -> 0.016963332
... A1260: 1258 | B1260: 118.8 | C1260: =LN(B1260/B1259) -> -0.019010067

Sheet GrupoMexico
B1: GMEXICOB.MX | C1: R_GMexico | E1: Rendimiento | F1: =AVERAGE(C:C) -> 0.00065383254
A2: 0 | B2: 48.509998 | E2: Varianza | F2: =_xlfn.VAR.S(C:C) -> 0.00058922952
A3: 1 | B3: 48.5 | C3: =LN(B3/B2) -> -0.00020612971 | E3: Volatilidad | F3: =SQRT(F2) -> 0.02427405
A4: 2 | B4: 49.849998 | C4: =LN(B4/B3) -> 0.027454668
A5: 3 | B5: 50.150002 | C5: =LN(B5/B4) -> 0.006000079
A6: 4 | B6: 51.34 | C6: =LN(B6/B5) -> 0.023451634
A7: 5 | B7: 51.259998 | C7: =LN(B7/B6) -> -0.0015594902
A8: 6 | B8: 50.669998 | C8: =LN(B8/B7) -> -0.011576705
A9: 7 | B9: 50.98 | C9: =LN(B9/B8) -> 0.0060994066
A10: 8 | B10: 52.540001 | C10: =LN(B10/B9) -> 0.030141412
A11: 9 | B11: 52.84 | C11: =LN(B11/B10) -> 0.0056936809
A12: 10 | B12: 52.650002 | C12: =LN(B12/B11) -> -0.003602215
A13: 11 | B13: 53.16 | C13: =LN(B13/B12) -> 0.0096399634
A14: 12 | B14: 52.82 | C14: =LN(B14/B13) -> -0.0064163299
A15: 13 | B15: 52.580002 | C15: =LN(B15/B14) -> -0.004554047
... A1260: 1258 | B1260: 110.42 | C1260: =LN(B1260/B1259) -> -0.017238694

Sheet FEMSA
B1: KOFUBL.MX | C1: R_FEMSA | E1: Rendimiento | F1: =AVERAGE(C:C) -> 0.00034343852
A2: 0 | B2: 110.01 | E2: Varianza | F2: =_xlfn.VAR.S(C:C) -> 0.00022409004
A3: 1 | B3: 107.7 | C3: =LN(B3/B2) -> -0.021221734 | E3: Volatilidad | F3: =SQRT(F2) -> 0.014969637
A4: 2 | B4: 107.14 | C4: =LN(B4/B3) -> -0.0052131711
A5: 3 | B5: 107.66 | C5: =LN(B5/B4) -> 0.0048417624
A6: 4 | B6: 108.25 | C6: =LN(B6/B5) -> 0.0054652197
A7: 5 | B7: 106.08 | C7: =LN(B7/B6) -> -0.020249823
A8: 6 | B8: 105.71 | C8: =LN(B8/B7) -> -0.0034940566
A9: 7 | B9: 109.45 | C9: =LN(B9/B8) -> 0.034768309
A10: 8 | B10: 109.58 | C10: =LN(B10/B9) -> 0.0011870967
A11: 9 | B11: 109.24 | C11: =LN(B11/B10) -> -0.0031076158
A12: 10 | B12: 109.51 | C12: =LN(B12/B11) -> 0.0024686117
A13: 11 | B13: 110.36 | C13: =LN(B13/B12) -> 0.0077318661
A14: 12 | B14: 110.74 | C14: =LN(B14/B13) -> 0.0034373372
A15: 13 | B15: 110.61 | C15: =LN(B15/B14) -> -0.0011745857
... A1260: 1258 | B1260: 169.46001 | C1260: =LN(B1260/B1259) -> -0.018128038

Sheet ASUR
B1: ASUR.MX | C1: ASURB_r | E1: Rendimiento | F1: =AVERAGE(C:C) -> 0.00047181429
A2: 0 | B2: 304.51999 | E2: Varianza | F2: =_xlfn.VAR.S(C:C) -> 0.00046946375
A3: 1 | B3: 311.34 | C3: =LN(B3/B2) -> 0.02214882 | E3: Volatilidad | F3: =SQRT(F2) -> 0.021667112
A4: 2 | B4: 313.67001 | C4: =LN(B4/B3) -> 0.0074559698
A5: 3 | B5: 322.16 | C5: =LN(B5/B4) -> 0.026706807
A6: 4 | B6: 318.82999 | C6: =LN(B6/B5) -> -0.010390325
A7: 5 | B7: 318.17001 | C7: =LN(B7/B6) -> -0.0020721299
A8: 6 | B8: 315.44 | C8: =LN(B8/B7) -> -0.008617376
A9: 7 | B9: 314.28 | C9: =LN(B9/B8) -> -0.0036841929
A10: 8 | B10: 313.97 | C10: =LN(B10/B9) -> -0.00098686059
A11: 9 | B11: 314.17001 | C11: =LN(B11/B10) -> 0.00063683959
A12: 10 | B12: 325.85999 | C12: =LN(B12/B11) -> 0.036533513
A13: 11 | B13: 329.26001 | C13: =LN(B13/B12) -> 0.010379946
A14: 12 | B14: 321.29001 | C14: =LN(B14/B13) -> -0.024503573
A15: 13 | B15: 325.57001 | C15: =LN(B15/B14) -> 0.013233346
... A1260: 1258 | B1260: 551.29999 | C1260: =LN(B1260/B1259) -> -0.012294881

Sheet Calculos
B2: MATRIZ DE VARIANZAS Y COVARIANZAS (Extendida) | K2: E(Ri) | O2: Cartera | Q2: W_BIMBO | R2: W_Carso | S2: W_GMex | T2: W_FEMSA | U2: W_ASUR | V2: Varianza | W2: Volatilidad | X2: Rendimiento | Z2: Factor | AB2: Volatiliad | AC2: rdiario
B3: BIMBO | C3: GrupoCarso | D3: GrupoMexico | E3: FEMSA | F3: ASUR | J3: GrupoModelo | K3: =BIMBO!F1 -> 0.0005193885 | O3: 1 | P3: CMR | Q3: {=TRANSPOSE(K13:K17)} -> 0.1665949 | R3: 0.043885534 | S3: 0.1171195 | T3: 0.50748512 | U3: 0.16491494 | V3: {=MMULT(MMULT(TRANSPOSE(K13:K17),B4:F8),K13:K17)} -> 0.00015480908 | W3: =SQRT(V3) -> 0.01244223 | X3: =SUMPRODUCT(K3:K7,K13:K17) -> 0.00043729233 | Y3: =X3 -> 0.00043729233 | Z3: =(X22-X3)/19 -> 8.779452e-06 | AA3: Risk Free | AB3: 0 | AC3: =K24 -> 0.00028333333
A4: BIMBO | B4: =_xlfn.VAR.S(BIMBO!C:C) -> 0.00046028742 | C4: =B5 -> 0.00018784825 | D4: =B6 -> 0.00011613405 | E4: =B7 -> 8.2977446e-05 | F4: =B8 -> 8.5937238e-05 | G4: 1 | J4: GrupoCarso | K4: =GrupoCarso!F1 -> 0.00050333563 | M4: {=MMULT(TRANSPOSE(Q4:U4),$B$4:$F$8)} -> #VALUE! | O4: 2 | Q4: =P27 -> 0.17523692 | R4: =Q27 -> 0.047590908 | S4: =R27 -> 0.13795409 | T4: =S27 -> 0.47274928 | U4: =T27 -> 0.1664688 | V4: {=MMULT(MMULT(Q4:U4, $B$4:$F$8), TRANSPOSE(Q4:U4))} -> 0.0001552737 | W4: =SQRT(V4) -> 0.012460887 | X4: {=SUMPRODUCT($K$3:$K$7, TRANSPOSE(Q4:U4))} -> 0.00044607179 | Y4: =Y3+$Z$3 -> 0.00044607179 | AA4: Portafolio | AB4: =W22 -> 0.01795939 | AC4: =X22 -> 0.00060410192
A5: GrupoCarso | B5: =COVAR(BIMBO!C:C,GrupoCarso!C:C) -> 0.00018784825 | C5: =_xlfn.VAR.S(GrupoCarso!C:C) -> 0.00061694381 | D5: =C6 -> 0.00015556553 | E5: =C7 -> 0.00011115052 | F5: =C8 -> 0.00013226584 | G5: 1 | J5: GrupoMexico | K5: =GrupoMexico!F1 -> 0.00065383254 | O5: 3 | Q5: =P28 -> 0.18387894 | R5: =Q28 -> 0.051296282 | S5: =R28 -> 0.15878868 | T5: =S28 -> 0.43801343 | U5: =T28 -> 0.16802267 | V5: {=MMULT(MMULT(Q5:U5, $B$4:$F$8), TRANSPOSE(Q5:U5))} -> 0.00015666759 | W5: =SQRT(V5) -> 0.012516692 | X5: {=SUMPRODUCT($K$3:$K$7, TRANSPOSE(Q5:U5))} -> 0.00045485124 | Y5: =Y4+$Z$3 -> 0.00045485124
A6: GrupoMexico | B6: =COVAR(GrupoMexico!C:C,BIMBO!C:C) -> 0.00011613405 | C6: =COVAR(GrupoMexico!C:C,GrupoCarso!C:C) -> 0.00015556553 | D6: =_xlfn.VAR.S(GrupoMexico!C:C) -> 0.00058922952 | E6: =D7 -> 7.4863853e-05 | F6: =D8 -> 0.00013117125 | G6: 1 | J6: FEMSA | K6: =FEMSA!F1 -> 0.00034343852 | O6: 4 | Q6: =P29 -> 0.19252095 | R6: =Q29 -> 0.055001656 | S6: =R29 -> 0.17962327 | T6: =S29 -> 0.40327758 | U6: =T29 -> 0.16957653 | V6: {=MMULT(MMULT(Q6:U6, $B$4:$F$8), TRANSPOSE(Q6:U6))} -> 0.00015899072 | W6: =SQRT(V6) -> 0.012609152 | X6: {=SUMPRODUCT($K$3:$K$7, TRANSPOSE(Q6:U6))} -> 0.00046363069 | Y6: =Y5+$Z$3 -> 0.00046363069 | AB6: Volatiliad | AC6: rdiario
A7: FEMSA | B7: =COVAR(FEMSA!C:C,BIMBO!C:C) -> 8.2977446e-05 | C7: =COVAR(FEMSA!C:C,GrupoCarso!C:C) -> 0.00011115052 | D7: =COVAR(FEMSA!C:C,GrupoMexico!C:C) -> 7.4863853e-05 | E7: =_xlfn.VAR.S(FEMSA!C:C) -> 0.00022409004 | F7: =E8 -> 8.2570925e-05 | G7: 1 | J7: ASUR | K7: =ASUR!F1 -> 0.00047181429 | O7: 5 | Q7: =P30 -> 0.20116297 | R7: =Q30 -> 0.05870703 | S7: =R30 -> 0.20045787 | T7: =S30 -> 0.36854174 | U7: =T30 -> 0.1711304 | V7: {=MMULT(MMULT(Q7:U7, $B$4:$F$8), TRANSPOSE(Q7:U7))} -> 0.00016224312 | W7: =SQRT(V7) -> 0.012737469 | X7: {=SUMPRODUCT($K$3:$K$7, TRANSPOSE(Q7:U7))} -> 0.00047241014 | Y7: =Y6+$Z$3 -> 0.00047241014 | AB7: 0.01795939 | AC7: =X22 -> 0.00060410192
A8: ASUR | B8: =COVAR(ASUR!C:C,BIMBO!C:C) -> 8.5937238e-05 | C8: =COVAR(ASUR!C:C,GrupoCarso!C:C) -> 0.00013226584 | D8: =COVAR(ASUR!C:C,GrupoMexico!C:C) -> 0.00013117125 | E8: =COVAR(ASUR!C:C,FEMSA!C:C) -> 8.2570925e-05 | F8: =_xlfn.VAR.S(ASUR!C:C) -> 0.00046946375 | G8: 1 | O8: 6 | Q8: =P31 -> 0.20980499 | R8: =Q31 -> 0.062412404 | S8: =R31 -> 0.22129246 | T8: =S31 -> 0.33380589 | U8: =T31 -> 0.17268426 | V8: {=MMULT(MMULT(Q8:U8, $B$4:$F$8), TRANSPOSE(Q8:U8))} -> 0.00016642477 | W8: =SQRT(V8) -> 0.012900572 | X8: {=SUMPRODUCT($K$3:$K$7, TRANSPOSE(Q8:U8))} -> 0.00048118959 | Y8: =Y7+$Z$3 -> 0.00048118959 | AB8: 0.02 | AC8: =K26*(AB8-AB7)+AC7 -> 0.00060457864
B9: 1 | C9: 1 | D9: 1 | E9: 1 | F9: 1 | G9: 0 | O9: 7 | Q9: =P32 -> 0.218447 | R9: =Q32 -> 0.066117777 | S9: =R32 -> 0.24212705 | T9: =S32 -> 0.29907005 | U9: =T32 -> 0.17423813 | V9: {=MMULT(MMULT(Q9:U9, $B$4:$F$8), TRANSPOSE(Q9:U9))} -> 0.00017153567 | W9: =SQRT(V9) -> 0.013097163 | X9: {=SUMPRODUCT($K$3:$K$7, TRANSPOSE(Q9:U9))} -> 0.00048996905 | Y9: =Y8+$Z$3 -> 0.00048996905
O10: 8 | Q10: =P33 -> 0.22708902 | R10: =Q33 -> 0.069823151 | S10: =R33 -> 0.26296164 | T10: =S33 -> 0.2643342 | U10: =T33 -> 0.17579199 | V10: {=MMULT(MMULT(Q10:U10, $B$4:$F$8), TRANSPOSE(Q10:U10))} -> 0.00017757583 | W10: =SQRT(V10) -> 0.013325758 | X10: {=SUMPRODUCT($K$3:$K$7, TRANSPOSE(Q10:U10))} -> 0.0004987485 | Y10: =Y9+$Z$3 -> 0.0004987485
O11: 9 | Q11: =P34 -> 0.23573104 | R11: =Q34 -> 0.073528525 | S11: =R34 -> 0.28379623 | T11: =S34 -> 0.22959836 | U11: =T34 -> 0.17734585 | V11: {=MMULT(MMULT(Q11:U11, $B$4:$F$8), TRANSPOSE(Q11:U11))} -> 0.00018454525 | W11: =SQRT(V11) -> 0.013584743 | X11: {=SUMPRODUCT($K$3:$K$7, TRANSPOSE(Q11:U11))} -> 0.00050752795 | Y11: =Y10+$Z$3 -> 0.00050752795
B12: Matriz inversa (extendida) | I12: Vec Aux | K12: wi (minima varianza) | O12: 10 | Q12: =P35 -> 0.24437305 | R12: =Q35 -> 0.077233899 | S12: =R35 -> 0.30463082 | T12: =S35 -> 0.19486251 | U12: =T35 -> 0.17889972 | V12: {=MMULT(MMULT(Q12:U12, $B$4:$F$8), TRANSPOSE(Q12:U12))} -> 0.00019244392 | W12: =SQRT(V12) -> 0.013872416 | X12: {=SUMPRODUCT($K$3:$K$7, TRANSPOSE(Q12:U12))} -> 0.0005163074 | Y12: =Y11+$Z$3 -> 0.0005163074
B13: {=MINVERSE(B4:G9)} -> 2425.5898 | C13: -650.32383 | D13: -381.41022 | E13: -1073.5972 | F13: -320.25859 | G13: 0.1665949 | I13: 0 | K13: {=MMULT(B13:G18,I13:I18)} -> 0.1665949 | O13: 11 | Q13: =P36 -> 0.25301507 | R13: =Q36 -> 0.080939273 | S13: =R36 -> 0.32546541 | T13: =S36 -> 0.16012666 | U13: =T36 -> 0.18045358 | V13: {=MMULT(MMULT(Q13:U13, $B$4:$F$8), TRANSPOSE(Q13:U13))} -> 0.00020127185 | W13: =SQRT(V13) -> 0.014187031 | X13: {=SUMPRODUCT($K$3:$K$7, TRANSPOSE(Q13:U13))} -> 0.00052508685 | Y13: =Y12+$Z$3 -> 0.00052508685
B14: -650.32383 | C14: 2030.3937 | D14: -315.69473 | E14: -735.46307 | F14: -328.91205 | G14: 0.043885534 | I14: 0 | K14: 0.043885534 | O14: 12 | Q14: =P37 -> 0.26165709 | R14: =Q37 -> 0.084644647 | S14: =R37 -> 0.3463 | T14: =S37 -> 0.12539082 | U14: =T37 -> 0.18200745 | V14: {=MMULT(MMULT(Q14:U14, $B$4:$F$8), TRANSPOSE(Q14:U14))} -> 0.00021102903 | W14: =SQRT(V14) -> 0.014526838 | X14: {=SUMPRODUCT($K$3:$K$7, TRANSPOSE(Q14:U14))} -> 0.00053386631 | Y14: =Y13+$Z$3 -> 0.00053386631
B15: -381.41022 | C15: -315.69473 | D15: 1850.3598 | E15: -661.96831 | F15: -491.28652 | G15: 0.1171195 | I15: 0 | K15: 0.1171195 | O15: 13 | Q15: =P38 -> 0.2702991 | R15: =Q38 -> 0.088350021 | S15: =R38 -> 0.36713459 | T15: =S38 -> 0.090654973 | U15: =T38 -> 0.18356131 | V15: {=MMULT(MMULT(Q15:U15, $B$4:$F$8), TRANSPOSE(Q15:U15))} -> 0.00022171547 | W15: =SQRT(V15) -> 0.014890113 | X15: {=SUMPRODUCT($K$3:$K$7, TRANSPOSE(Q15:U15))} -> 0.00054264576 | Y15: =Y14+$Z$3 -> 0.00054264576
B16: -1073.5972 | C16: -735.46307 | D16: -661.96831 | E16: 3595.7597 | F16: -1124.7311 | G16: 0.50748512 | I16: 0 | K16: 0.50748512 | O16: 14 | Q16: =P39 -> 0.27894112 | R16: =Q39 -> 0.092055395 | S16: =R39 -> 0.38796918 | T16: =S39 -> 0.055919127 | U16: =T39 -> 0.18511518 | V16: {=MMULT(MMULT(Q16:U16, $B$4:$F$8), TRANSPOSE(Q16:U16))} -> 0.00023333116 | W16: =SQRT(V16) -> 0.015275181 | X16: {=SUMPRODUCT($K$3:$K$7, TRANSPOSE(Q16:U16))} -> 0.00055142521 | Y16: =Y15+$Z$3 -> 0.00055142521
B17: -320.25859 | C17: -328.91205 | D17: -491.28652 | E17: -1124.7311 | F17: 2265.1883 | G17: 0.16491494 | I17: 0 | K17: 0.16491494 | O17: 15 | Q17: =P40 -> 0.28758313 | R17: =Q40 -> 0.095760769 | S17: =R40 -> 0.40880377 | T17: =S40 -> 0.021183281 | U17: =T40 -> 0.18666904 | V17: {=MMULT(MMULT(Q17:U17, $B$4:$F$8), TRANSPOSE(Q17:U17))} -> 0.00024587611 | W17: =SQRT(V17) -> 0.015680437 | X17: {=SUMPRODUCT($K$3:$K$7, TRANSPOSE(Q17:U17))} -> 0.00056020466 | Y17: =Y16+$Z$3 -> 0.00056020466
B18: 0.1665949 | C18: 0.043885534 | D18: 0.1171195 | E18: 0.50748512 | F18: 0.16491494 | G18: -0.00015480908 | I18: 1 | K18: -0.00015480908 | O18: 16 | Q18: =P41 -> 0.29622515 | R18: =Q41 -> 0.099466142 | S18: =R41 -> 0.42963836 | T18: =S41 -> -0.013552564 | U18: =T41 -> 0.18822291 | V18: {=MMULT(MMULT(Q18:U18, $B$4:$F$8), TRANSPOSE(Q18:U18))} -> 0.00025935032 | W18: =SQRT(V18) -> 0.016104357 | X18: {=SUMPRODUCT($K$3:$K$7, TRANSPOSE(Q18:U18))} -> 0.00056898411 | Y18: =Y17+$Z$3 -> 0.00056898411
O19: 17 | Q19: =P42 -> 0.30486717 | R19: =Q42 -> 0.10317152 | S19: =R42 -> 0.45047295 | T19: =S42 -> -0.04828841 | U19: =T42 -> 0.18977677 | V19: {=MMULT(MMULT(Q19:U19, $B$4:$F$8), TRANSPOSE(Q19:U19))} -> 0.00027375378 | W19: =SQRT(V19) -> 0.016545506 | X19: {=SUMPRODUCT($K$3:$K$7, TRANSPOSE(Q19:U19))} -> 0.00057776357 | Y19: =Y18+$Z$3 -> 0.00057776357
O20: 18 | Q20: =P43 -> 0.31350918 | R20: =Q43 -> 0.10687689 | S20: =R43 -> 0.47130755 | T20: =S43 -> -0.083024256 | U20: =T43 -> 0.19133064 | V20: {=MMULT(MMULT(Q20:U20, $B$4:$F$8), TRANSPOSE(Q20:U20))} -> 0.00028908649 | W20: =SQRT(V20) -> 0.017002544 | X20: {=SUMPRODUCT($K$3:$K$7, TRANSPOSE(Q20:U20))} -> 0.00058654302 | Y20: =Y19+$Z$3 -> 0.00058654302
O21: 19 | Q21: =P44 -> 0.3221512 | R21: =Q44 -> 0.11058226 | S21: =R44 -> 0.49214214 | T21: =S44 -> -0.1177601 | U21: =T44 -> 0.1928845 | V21: {=MMULT(MMULT(Q21:U21, $B$4:$F$8), TRANSPOSE(Q21:U21))} -> 0.00030534846 | W21: =SQRT(V21) -> 0.017474223 | X21: {=SUMPRODUCT($K$3:$K$7, TRANSPOSE(Q21:U21))} -> 0.00059532247 | Y21: =Y20+$Z$3 -> 0.00059532247
B22: MATRIZ AUXILIAR | O22: 20 | P22: CM | Q22: {=TRANSPOSE(L32:L36)} -> 0.33079322 | R22: 0.11428764 | S22: 0.51297673 | T22: -0.15249595 | U22: 0.19443837 | V22: {=MMULT(MMULT(TRANSPOSE(L32:L36),B4:F8),L32:L36)} -> 0.00032253969 | W22: =SQRT(V22) -> 0.01795939 | X22: {=SUMPRODUCT($K$3:$K$7, TRANSPOSE(Q22:U22))} -> 0.00060410192 | Y22: =Y21+$Z$3 -> 0.00060410192
B23: =_xlfn.VAR.S(BIMBO!C:C) -> 0.00046028742 | C23: =B24 -> 0.00018784825 | D23: =B25 -> 0.00011613405 | E23: =B26 -> 8.2977446e-05 | F23: =B27 -> 8.5937238e-05 | G23: 1 | H23: {=TRANSPOSE(B29:F29)} -> 0.0005193885 | J23: Rf | K23: =0.102 -> 0.102
B24: =COVAR(BIMBO!C:C,GrupoCarso!C:C) -> 0.00018784825 | C24: =_xlfn.VAR.S(GrupoCarso!C:C) -> 0.00061694381 | D24: =C25 -> 0.00015556553 | E24: =C26 -> 0.00011115052 | F24: =C27 -> 0.00013226584 | G24: 1 | H24: 0.00050333563 | J24: Rf diaria | K24: =K23/360 -> 0.00028333333
B25: =COVAR(GrupoMexico!C:C,BIMBO!C:C) -> 0.00011613405 | C25: =COVAR(GrupoMexico!C:C,GrupoCarso!C:C) -> 0.00015556553 | D25: =_xlfn.VAR.S(GrupoMexico!C:C) -> 0.00058922952 | E25: =D26 -> 7.4863853e-05 | F25: =D27 -> 0.00013117125 | G25: 1 | H25: 0.00065383254 | J25: Préstamo anual | K25: 0.089
B26: =COVAR(FEMSA!C:C,BIMBO!C:C) -> 8.2977446e-05 | C26: =COVAR(FEMSA!C:C,GrupoCarso!C:C) -> 0.00011115052 | D26: =COVAR(FEMSA!C:C,GrupoMexico!C:C) -> 7.4863853e-05 | E26: =_xlfn.VAR.S(FEMSA!C:C) -> 0.00022409004 | F26: =E27 -> 8.2570925e-05 | G26: 1 | H26: 0.00034343852 | J26: Préstamo diario | K26: =(1+K25)^(1/365)-1 -> 0.0002336159 | P26: BIMBO | Q26: GrupoCarso | R26: GrupoMexico | S26: FEMSA | T26: ASUR
B27: =COVAR(ASUR!C:C,BIMBO!C:C) -> 8.5937238e-05 | C27: =COVAR(ASUR!C:C,GrupoCarso!C:C) -> 0.00013226584 | D27: =COVAR(ASUR!C:C,GrupoMexico!C:C) -> 0.00013117125 | E27: =COVAR(ASUR!C:C,FEMSA!C:C) -> 8.2570925e-05 | F27: =_xlfn.VAR.S(ASUR!C:C) -> 0.00046946375 | G27: 1 | H27: 0.00047181429 | J27: https://www.yotepresto.com/prestamos-personales?utm_source=googleads&utm_medium=g&utm_content=79605897483:626835688024&utm_campaign=6944045184&utm_term=kwd-14280251&keyword=prestamos&adposition=&gad_source=1&gbraid=0AAAAADcws_xJ-xHGQD9lS5VKXullXyWSy&gclid=Cj0KCQiA88a5BhDPARIsAFj595iRg0Cm058UDves8XV4Z5H1MgPcfJWBM40iceRNkh_Mzv95fgJbtvkaApyTEALw_wcB#simulator | P27: {=TRANSPOSE(MMULT($B$41:$H$47,B51:B57))} -> 0.17523692 | Q27: 0.047590908 | R27: 0.13795409 | S27: 0.47274928 | T27: 0.1664688 | U27: -0.00013166661 | V27: -0.05292218 | W27: =SUM(P27:T27) -> 1
B28: 1 | C28: 1 | D28: 1 | E28: 1 | F28: 1 | G28: 0 | H28: 0 | P28: {=TRANSPOSE(MMULT($B$41:$H$47,C51:C57))} -> 0.18387894 | Q28: 0.051296282 | R28: 0.15878868 | S28: 0.43801343 | T28: 0.16802267 | U28: -0.00010852415 | V28: -0.10584436 | W28: =SUM(P28:T28) -> 1
B29: {=TRANSPOSE(K3:K7)} -> 0.0005193885 | C29: 0.00050333563 | D29: 0.00065383254 | E29: 0.00034343852 | F29: 0.00047181429 | G29: 0 | H29: 0 | P29: {=TRANSPOSE(MMULT($B$41:$H$47,D51:D57))} -> 0.19252095 | Q29: 0.055001656 | R29: 0.17962327 | S29: 0.40327758 | T29: 0.16957653 | U29: -8.5381684e-05 | V29: -0.15876654 | W29: =SUM(P29:T29) -> 1
P30: {=TRANSPOSE(MMULT($B$41:$H$47,E51:E57))} -> 0.20116297 | Q30: 0.05870703 | R30: 0.20045787 | S30: 0.36854174 | T30: 0.1711304 | U30: -6.223922e-05 | V30: -0.21168872 | W30: =SUM(P30:T30) -> 1
B31: Matriz Inversa | H31: E(Ri) - rf | J31: Ui | L31: wi (de mercado) | P31: {=TRANSPOSE(MMULT($B$41:$H$47,F51:F57))} -> 0.20980499 | Q31: 0.062412404 | R31: 0.22129246 | S31: 0.33380589 | T31: 0.17268426 | U31: -3.9096756e-05 | V31: -0.2646109 | W31: =SUM(P31:T31) -> 1
B32: {=MINVERSE(B23:F27)} -> 2604.8679 | C32: -603.09723 | D32: -255.37425 | E32: -527.47653 | F32: -142.78845 | H32: =K3-$K$24 -> 0.00023605516 | J32: {=MMULT(B32:F36,H32:H36)} -> 0.32897679 | L32: =J32/$J$37 -> 0.33079322 | P32: {=TRANSPOSE(MMULT($B$41:$H$47,G51:G57))} -> 0.218447 | Q32: 0.066117777 | R32: 0.24212705 | S32: 0.29907005 | T32: 0.17423813 | U32: -1.5954292e-05 | V32: -0.31753308 | W32: =SUM(P32:T32) -> 1
B33: -603.09723 | C33: 2042.8344 | D33: -282.4935 | E33: -591.60035 | F33: -282.16169 | H33: =K4-$K$24 -> 0.00022000229 | J33: 0.11366007 | L33: =J33/$J$37 -> 0.11428764 | P33: {=TRANSPOSE(MMULT($B$41:$H$47,H51:H57))} -> 0.22708902 | Q33: 0.069823151 | R33: 0.26296164 | S33: 0.2643342 | T33: 0.17579199 | U33: 7.1881719e-06 | V33: -0.37045526 | W33: =SUM(P33:T33) -> 1
B34: -255.37425 | C34: -282.4935 | D34: 1938.9655 | E34: -278.03471 | F34: -366.52151 | H34: =K5-$K$24 -> 0.0003704992 | J34: 0.51015991 | L34: =J34/$J$37 -> 0.51297673 | P34: {=TRANSPOSE(MMULT($B$41:$H$47,I51:I57))} -> 0.23573104 | Q34: 0.073528525 | R34: 0.28379623 | S34: 0.22959836 | T34: 0.17734585 | U34: 3.0330636e-05 | V34: -0.42337744 | W34: =SUM(P34:T34) -> 1 | AB34: FIGURA 2.1
B35: -527.47653 | C35: -591.60035 | D35: -278.03471 | E35: 5259.3647 | F35: -584.11764 | H35: =K6-$K$24 -> 6.0105188e-05 | J35: -0.15165858 | L35: =J35/$J$37 -> -0.15249595 | P35: {=TRANSPOSE(MMULT($B$41:$H$47,J51:J57))} -> 0.24437305 | Q35: 0.077233899 | R35: 0.30463082 | S35: 0.19486251 | T35: 0.17889972 | U35: 5.34731e-05 | V35: -0.47629962 | W35: =SUM(P35:T35) -> 1
B36: -142.78845 | C36: -282.16169 | D36: -366.52151 | E36: -584.11764 | F36: 2440.8688 | H36: =K7-$K$24 -> 0.00018848095 | J36: 0.19337068 | L36: =J36/$J$37 -> 0.19443837 | P36: {=TRANSPOSE(MMULT($B$41:$H$47,K51:K57))} -> 0.25301507 | Q36: 0.080939273 | R36: 0.32546541 | S36: 0.16012666 | T36: 0.18045358 | U36: 7.6615564e-05 | V36: -0.5292218 | W36: =SUM(P36:T36) -> 1
J37: =SUM(J32:J36) -> 0.99450889 | P37: {=TRANSPOSE(MMULT($B$41:$H$47,L51:L57))} -> 0.26165709 | Q37: 0.084644647 | R37: 0.3463 | S37: 0.12539082 | T37: 0.18200745 | U37: 9.9758027e-05 | V37: -0.58214399 | W37: =SUM(P37:T37) -> 1
P38: {=TRANSPOSE(MMULT($B$41:$H$47,M51:M57))} -> 0.2702991 | Q38: 0.088350021 | R38: 0.36713459 | S38: 0.090654973 | T38: 0.18356131 | U38: 0.00012290049 | V38: -0.63506617 | W38: =SUM(P38:T38) -> 1
P39: {=TRANSPOSE(MMULT($B$41:$H$47,N51:N57))} -> 0.27894112 | Q39: 0.092055395 | R39: 0.38796918 | S39: 0.055919127 | T39: 0.18511518 | U39: 0.00014604296 | V39: -0.68798835 | W39: =SUM(P39:T39) -> 1
B40: MATRIZ AUXILIAR (Inversa) | J40: Vector auxiliar | L40: WFE | P40: {=TRANSPOSE(MMULT($B$41:$H$47,O51:O57))} -> 0.28758313 | Q40: 0.095760769 | R40: 0.40880377 | S40: 0.021183281 | T40: 0.18666904 | U40: 0.00016918542 | V40: -0.74091053 | W40: =SUM(P40:T40) -> 1
B41: {=MINVERSE(B23:H29)} -> 2264.8495 | C41: -719.24331 | D41: -768.93094 | E41: -427.51493 | F41: -349.16028 | G41: -0.26385195 | H41: 984.34577 | J41: 0 | L41: {=MMULT(B41:H47,J41:J47)} -> -0.32904037 | P41: {=TRANSPOSE(MMULT($B$41:$H$47,P51:P57))} -> 0.29622515 | Q41: 0.099466142 | R41: 0.42963836 | S41: -0.013552564 | T41: 0.18822291 | U41: 0.00019232788 | V41: -0.79383271 | W41: =SUM(P41:T41) -> 1
...

Sheet Hoja 7
E4: PORTAFOLIO DE MINIMA VARIANZA | L4: Portafolio Optimo
B5: Capital | C5: Y | D5: rf | E5: PR | F5: BIMBO | G5: GrupoCarso | H5: GrupoMexico | I5: FEMSA | J5: ASUR | K5: BIMBO | L5: GrupoCarso | M5: GrupoMexico | N5: FEMSA | O5: ASUR | P5: E(RMV) | Q5: Prima de Riesgo
A6: inversor 1 | B6: 50000000 | C6: 0.6 | D6: =C6*B6 -> 30000000 | E6: =B6-D6 -> 20000000 | F6: =Calculos!Q3*E6 -> 3331898.1 | G6: =Calculos!R3*E6 -> 877710.68 | H6: =Calculos!S3*E6 -> 2342390.1 | I6: =Calculos!T3*E6 -> 10149702 | J6: =Calculos!U3*E6 -> 3298298.7 | K6: =Calculos!$Q$22*D6 -> 9923796.5 | L6: =Calculos!$R$22*D6 -> 3428629.1 | M6: =Calculos!$S$22*D6 -> 15389302 | N6: =Calculos!$T$22*D6 -> -4574878.4 | O6: =Calculos!$U$22*D6 -> 5833151 | P6: =C6*Calculos!X3+(1-C6)*Calculos!K24 -> 0.00037570873 | Q6: =P6-Calculos!K24 -> 9.2375401e-05
A7: inversor 2 | B7: 500000 | C7: 0.5 | D7: =C7*B7 -> 250000 | E7: =B7-D7 -> 250000 | F7: =Calculos!Q4*E7 -> 43809.23 | G7: =Calculos!R4*E7 -> 11897.727 | H7: =Calculos!S4*E7 -> 34488.523 | I7: =Calculos!T4*E7 -> 118187.32 | J7: =Calculos!U4*E7 -> 41617.2 | K7: =Calculos!$Q$22*D7 -> 82698.304 | L7: =Calculos!$R$22*D7 -> 28571.909 | M7: =Calculos!$S$22*D7 -> 128244.18 | N7: =Calculos!$T$22*D7 -> -38123.987 | O7: =Calculos!$U$22*D7 -> 48609.591 | P7: =C7*Calculos!X4+(1-C7)*Calculos!K25 -> 0.044723036 | Q7: =P7-Calculos!K25 -> -0.044276964
A8: inversor 3 | B8: 700000 | C8: 0.75 | D8: =C8*B8 -> 525000 | E8: =B8-D8 -> 175000 | F8: =Calculos!Q5*E8 -> 32178.814 | G8: =Calculos!R5*E8 -> 8976.8493 | H8: =Calculos!S5*E8 -> 27788.02 | I8: =Calculos!T5*E8 -> 76652.35 | J8: =Calculos!U5*E8 -> 29403.967 | K8: =Calculos!$Q$22*D8 -> 173666.44 | L8: =Calculos!$R$22*D8 -> 60001.01 | M8: =Calculos!$S$22*D8 -> 269312.78 | N8: =Calculos!$T$22*D8 -> -80060.372 | O8: =Calculos!$U$22*D8 -> 102080.14 | P8: =C8*Calculos!X5+(1-C8)*Calculos!K26 -> 0.0003995424 | Q8: =P8-Calculos!K26 -> 0.00016592651
A9: inversor 4 | B9: 100000 | C9: 1.5 | D9: =C9*B9 -> 150000 | E9: =B9-D9 -> -50000 | F9: =Calculos!Q6*E9 -> -9626.0477 | G9: =Calculos!R6*E9 -> -2750.0828 | H9: =Calculos!S6*E9 -> -8981.1637 | I9: =Calculos!T6*E9 -> -20163.879 | J9: =Calculos!U6*E9 -> -8478.8265 | K9: =Calculos!$Q$22*D9 -> 49618.982 | L9: =Calculos!$R$22*D9 -> 17143.146 | M9: =Calculos!$S$22*D9 -> 76946.509 | N9: =Calculos!$T$22*D9 -> -22874.392 | O9: =Calculos!$U$22*D9 -> 29165.755 | P9: =C9*Calculos!X6+(1-C9)*Calculos!K27 -> 0.00069544604 | Q9: =P9-Calculos!K27 -> 0.00069544604
E12: PORTAFOLIO DE MINIMA VARIANZA | L12: Portafolio Optimo
B13: Capital | C13: Y | D13: rf | E13: PR | F13: BIMBO | G13: GrupoCarso | H13: GrupoMexico | I13: FEMSA | J13: ASUR | K13: Bimbo | L13: GrupoCarso | M13: GrupoMexico | N13: FEMSA | O13: ASUR | P13: E(RMV) | Q13: Prima de Riesgo
A14: inversor 1 | B14: 50000000 | C14: 0.4 | D14: =C14*B14 -> 20000000 | E14: =B14-D14 -> 30000000 | F14: =Calculos!Q11*E14 -> 7071931.1 | G14: =Calculos!R11*E14 -> 2205855.8 | H14: =Calculos!S11*E14 -> 8513886.9 | I14: =Calculos!T11*E14 -> 6887950.7 | J14: =Calculos!U11*E14 -> 5320375.6 | K14: =Calculos!$Q$22*D14 -> 6615864.3 | L14: =Calculos!$R$22*D14 -> 2285752.8 | M14: =Calculos!$S$22*D14 -> 10259535 | N14: =Calculos!$T$22*D14 -> -3049918.9 | O14: =Calculos!$U$22*D14 -> 3888767.3 | P14: =C14*Calculos!X11+(1-C14)*Calculos!K32 -> 0.00020301118 | Q14: =P14-Calculos!K32 -> 0.00020301118
A15: inversor 2 | B15: 500000 | C15: 0.6 | D15: =C15*B15 -> 300000 | E15: =B15-D15 -> 200000 | F15: =Calculos!Q12*E15 -> 48874.611 | G15: =Calculos!R12*E15 -> 15446.78 | H15: =Calculos!S12*E15 -> 60926.164 | I15: =Calculos!T12*E15 -> 38972.502 | J15: =Calculos!U12*E15 -> 35779.944 | K15: =Calculos!$Q$22*D15 -> 99237.965 | L15: =Calculos!$R$22*D15 -> 34286.291 | M15: =Calculos!$S$22*D15 -> 153893.02 | N15: =Calculos!$T$22*D15 -> -45748.784 | O15: =Calculos!$U$22*D15 -> 58331.51 | P15: =C15*Calculos!X12+(1-C15)*Calculos!K33 -> 0.00030978444 | Q15: =P15-Calculos!K33 -> 0.00030978444
A16: inversor 3 | B16: 700000 | C16: 1.2 | D16: =C16*B16 -> 840000 | E16: =B16-D16 -> -140000 | F16: =Calculos!Q13*E16 -> -35422.11 | G16: =Calculos!R13*E16 -> -11331.498 | H16: =Calculos!S13*E16 -> -45565.157 | I16: =Calculos!T13*E16 -> -22417.733 | J16: =Calculos!U13*E16 -> -25263.502 | K16: =Calculos!$Q$22*D16 -> 277866.3 | L16: =Calculos!$R$22*D16 -> 96001.616 | M16: =Calculos!$S$22*D16 -> 430900.45 | N16: =Calculos!$T$22*D16 -> -128096.6 | O16: =Calculos!$U$22*D16 -> 163328.23 | P16: =C16*Calculos!X13+(1-C16)*Calculos!K34 -> 0.00063010423 | Q16: =P16-Calculos!K34 -> 0.00063010423
A17: inversor 4 | B17: 100000 | C17: 0.9 | D17: =C17*B17 -> 90000 | E17: =B17-D17 -> 10000 | F17: =Calculos!Q14*E17 -> 2616.5709 | G17: =Calculos!R14*E17 -> 846.44647 | H17: =Calculos!S14*E17 -> 3463 | I17: =Calculos!T14*E17 -> 1253.9082 | J17: =Calculos!U14*E17 -> 1820.0745 | K17: =Calculos!$Q$22*D17 -> 29771.389 | L17: =Calculos!$R$22*D17 -> 10285.887 | M17: =Calculos!$S$22*D17 -> 46167.905 | N17: =Calculos!$T$22*D17 -> -13724.635 | O17: =Calculos!$U$22*D17 -> 17499.453 | P17: =C17*Calculos!X14+(1-C17)*Calculos!K35 -> 0.00048047968 | Q17: =P17-Calculos!K35 -> 0.00048047968
F19: =F6-F14 -> -3740033 | G19: =G6-G14 -> -1328145.1 | H19: =H6-H14 -> -6171496.8 | I19: =I6-I14 -> 3261751.8 | J19: =J6-J14 -> -2022076.9 | K19: =K6-K14 -> 3307932.2 | L19: =L6-L14 -> 1142876.4 | M19: =M6-M14 -> 5129767.3 | ... O19: =O6-O14 -> 1944383.7
F20: =F7-F15 -> -5065.3802 | G20: =G7-G15 -> -3549.0528 | H20: =H7-H15 -> -26437.641 | I20: =I7-I15 -> 79214.817 | J20: =J7-J15 -> 5837.2566 | K20: =K7-K15 -> -16539.661 | L20: =L7-L15 -> -5714.3819 | M20: =M7-M15 -> -25648.836 | ... O20: =O7-O15 -> -9721.9183
F21: =F8-F16 -> 67600.924 | G21: =G8-G16 -> 20308.348 | H21: =H8-H16 -> 73353.177 | I21: =I8-I16 -> 99070.083 | J21: =J8-J16 -> 54667.468 | K21: =K8-K16 -> -104199.86 | L21: =L8-L16 -> -36000.606 | M21: =M8-M16 -> -161587.67 | ... O21: =O8-O16 -> -61248.085
F22: =F9-F17 -> -12242.619 | G22: =G9-G17 -> -3596.5293 | H22: =H9-H17 -> -12444.164 | I22: =I9-I17 -> -21417.787 | J22: =J9-J17 -> -10298.901 | K22: =K9-K17 -> 19847.593 | L22: =L9-L17 -> 6857.2583 | M22: =M9-M17 -> 30778.604 | ... O22: =O9-O17 -> 11666.302
