Workbook

Sheet adj_close
A1: Date | B1: BIMBOA | C1: GCARSOA1 | D1: GMEXICOB | E1: KOFUBL | F1: ALSEA
A2: 43973 | B2: 32.737141 | C2: 44.877823 | D2: 38.17725 | E2: 74.587303 | F2: 17.997326
A3: 43976 | B3: 32.479221 | C3: 44.397087 | D3: 37.633049 | E3: 74.693283 | F3: 17.559082
A4: 43977 | B4: 33.004269 | C4: 44.830692 | D4: 37.335884 | E4: 75.777565 | F4: 18.474529
A5: 43978 | B5: 33.188499 | C5: 45.358559 | D5: 37.716862 | E5: 78.370064 | F5: 18.659567
A6: 43979 | B6: 32.359478 | C6: 44.4725 | D6: 37.434948 | E6: 76.706963 | F6: 18.416096
A7: 43980 | B7: 31.935751 | C7: 47.121246 | D7: 36.177715 | E7: 78.908127 | F7: 18.260275
A8: 43983 | B8: 33.520107 | C8: 46.320026 | D8: 37.975933 | E8: 77.734161 | F8: 18.669306
A9: 43984 | B9: 34.118847 | C9: 47.658535 | D9: 39.019821 | E9: 79.111946 | F9: 19.36076
A10: 43985 | B10: 33.676701 | C10: 47.922466 | D10: 38.699795 | E10: 80.261444 | F10: 20.393076
A11: 43986 | B11: 33.031906 | C11: 47.28149 | D11: 38.501682 | E11: 79.046715 | F11: 21.181919
A12: 43987 | B12: 32.488438 | C12: 50.052769 | D12: 40.147514 | E12: 81.549538 | F12: 23.295242
A13: 43990 | B13: 33.40036 | C13: 50.608913 | D13: 40.741837 | E13: 84.476303 | F13: 24.639196
... A1258: 45797 | B1258: 55.41 | C1258: 124.56439 | D1258: 101.67765 | E1258: 175.29042 | F1258: 46.862888

Sheet BIMBO
B1: BIMBOA.MX | C1: R_BIMBO | E1: Rendimiento | F1: =AVERAGE(C3:C1260) -> 0.12041976
A2: 0 | B2: 32.737141 | E2: Varianza | F2: =_xlfn.VAR.S(C:C) -> 0.086213363
A3: 1 | B3: 32.479221 | E3: Volatilidad | F3: =SQRT(F2) -> 0.29362112
A4: 2 | B4: 33.004269
A5: 3 | B5: 33.188499
A6: 4 | B6: 32.359478
A7: 5 | B7: 31.935751
A8: 6 | B8: 33.520107
A9: 7 | B9: 34.118847
A10: 8 | B10: 33.676701
A11: 9 | B11: 33.031906
A12: 10 | B12: 32.488438
A13: 11 | B13: 33.40036
A14: 12 | B14: 32.755566
A15: 13 | B15: 32.543701
... A253: 251 | B253: 37.797089
A254: 252 | B254: 38.250427 | C254: =LN(B254/B2) -> 0.1556445
A255: 253 | B255: 38.958767 | C255: =LN(B255/B3) -> 0.18190329
A256: 254 | B256: 40.186558 | C256: =LN(B256/B4) -> 0.19689565
A257: 255 | B257: 40.838234 | C257: =LN(B257/B5) -> 0.20741534
A258: 256 | B258: 40.885456 | C258: =LN(B258/B6) -> 0.23386744
A259: 257 | B259: 41.414349 | C259: =LN(B259/B7) -> 0.2599013
A260: 258 | B260: 41.140461 | C260: =LN(B260/B8) -> 0.20484661
A261: 259 | B261: 41.263237 | C261: =LN(B261/B9) -> 0.19012203
A262: 260 | B262: 41.744911 | C262: =LN(B262/B10) -> 0.21477134
A263: 261 | B263: 41.319904 | C263: =LN(B263/B11) -> 0.22387038
A264: 262 | B264: 41.801579 | C264: =LN(B264/B12) -> 0.25204984
A265: 263 | B265: 42.755482 | C265: =LN(B265/B13) -> 0.24693073
... A1258: 1256 | B1258: 55.41 | C1258: =LN(B1258/B1006) -> -0.23708224

Sheet GrupoCarso
B1: GCARSOA1.MX | C1: R_GCarso | E1: Rendimiento | F1: =AVERAGE(C:C) -> 0.23729508
A2: 0 | B2: 44.877823 | E2: Varianza | F2: =_xlfn.VAR.S(C:C) -> 0.072253923
A3: 1 | B3: 44.397087 | E3: Volatilidad | F3: =SQRT(F2) -> 0.2688009
A4: 2 | B4: 44.830692
A5: 3 | B5: 45.358559
A6: 4 | B6: 44.4725
A7: 5 | B7: 47.121246
A8: 6 | B8: 46.320026
A9: 7 | B9: 47.658535
A10: 8 | B10: 47.922466
A11: 9 | B11: 47.28149
A12: 10 | B12: 50.052769
A13: 11 | B13: 50.608913
A14: 12 | B14: 48.817947
A15: 13 | B15: 47.630253
... A253: 251 | B253: 53.832649
A254: 252 | B254: 53.71011 | C254: =LN(B254/B2) -> 0.1796575
A255: 253 | B255: 52.484718 | C255: =LN(B255/B3) -> 0.16734819
A256: 254 | B256: 53.097416 | C256: =LN(B256/B4) -> 0.16923526
A257: 255 | B257: 55.001492 | C257: =LN(B257/B5) -> 0.19276142
A258: 256 | B258: 56.5191 | C258: =LN(B258/B6) -> 0.23970762
A259: 257 | B259: 56.820736 | C259: =LN(B259/B7) -> 0.18717734
A260: 258 | B260: 59.309235 | C260: =LN(B260/B8) -> 0.24719062
A261: 259 | B261: 61.194462 | C261: =LN(B261/B9) -> 0.24999496
A262: 260 | B262: 59.290386 | C262: =LN(B262/B10) -> 0.21286275
A263: 261 | B263: 60.440372 | C263: =LN(B263/B11) -> 0.24553841
A264: 262 | B264: 61.486675 | C264: =LN(B264/B12) -> 0.20574267
A265: 263 | B265: 62.910015 | C265: =LN(B265/B13) -> 0.21757766
... A1258: 1256 | B1258: 124.56439 | C1258: =LN(B1258/B1006) -> -0.16138792

Sheet GrupoMexico
B1: GMEXICOB.MX | C1: R_GMexico | E1: Rendimiento | F1: =AVERAGE(C:C) -> 0.14147764
A2: 0 | B2: 38.17725 | E2: Varianza | F2: =_xlfn.VAR.S(C:C) -> 0.044911725
A3: 1 | B3: 37.633049 | E3: Volatilidad | F3: =SQRT(F2) -> 0.21192387
A4: 2 | B4: 37.335884
A5: 3 | B5: 37.716862
A6: 4 | B6: 37.434948
A7: 5 | B7: 36.177715
A8: 6 | B8: 37.975933
A9: 7 | B9: 39.019821
A10: 8 | B10: 38.699795
A11: 9 | B11: 38.501682
A12: 10 | B12: 40.147514
A13: 11 | B13: 40.741837
A14: 12 | B14: 40.284657
A15: 13 | B15: 40.254189
... A253: 251 | B253: 75.939575
A254: 252 | B254: 74.567955 | C254: =LN(B254/B2) -> 0.66947107
A255: 253 | B255: 73.319084 | C255: =LN(B255/B3) -> 0.6669383
A256: 254 | B256: 73.842804 | C256: =LN(B256/B4) -> 0.68198366
A257: 255 | B257: 74.809647 | C257: =LN(B257/B5) -> 0.68483959
A258: 256 | B258: 77.017273 | C258: =LN(B258/B6) -> 0.72142501
A259: 257 | B259: 78.266113 | C259: =LN(B259/B7) -> 0.7716714
A260: 258 | B260: 78.040512 | C260: =LN(B260/B8) -> 0.72027546
A261: 259 | B261: 78.967079 | C261: =LN(B261/B9) -> 0.70496129
A262: 260 | B262: 78.701187 | C262: =LN(B262/B10) -> 0.70982394
A263: 261 | B263: 80.320671 | C263: =LN(B263/B11) -> 0.73532508
A264: 262 | B264: 74.833817 | C264: =LN(B264/B12) -> 0.62270935
A265: 263 | B265: 73.270744 | C265: =LN(B265/B13) -> 0.58690592
... A1258: 1256 | B1258: 101.67765 | C1258: =LN(B1258/B1006) -> 0.028787107

Sheet FEMSA
B1: KOFUBL.MX | C1: R_FEMSA | E1: Rendimiento | F1: =AVERAGE(C:C) -> 0.18632399
A2: 0 | B2: 74.587303 | E2: Varianza | F2: =_xlfn.VAR.S(C:C) -> 0.0072236284
A3: 1 | B3: 74.693283 | E3: Volatilidad | F3: =SQRT(F2) -> 0.084991931
A4: 2 | B4: 75.777565
A5: 3 | B5: 78.370064
A6: 4 | B6: 76.706963
A7: 5 | B7: 78.908127
A8: 6 | B8: 77.734161
A9: 7 | B9: 79.111946
A10: 8 | B10: 80.261444
A11: 9 | B11: 79.046715
A12: 10 | B12: 81.549538
A13: 11 | B13: 84.476303
A14: 12 | B14: 82.788719
A15: 13 | B15: 79.910881
... A253: 251 | B253: 84.838593
A254: 252 | B254: 84.094704 | C254: =LN(B254/B2) -> 0.11997329
A255: 253 | B255: 83.039413 | C255: =LN(B255/B3) -> 0.10592519
A256: 254 | B256: 83.471909 | C256: =LN(B256/B4) -> 0.096707878
A257: 255 | B257: 83.056702 | C257: =LN(B257/B5) -> 0.058081512
A258: 256 | B258: 84.328247 | C258: =LN(B258/B6) -> 0.094724406
A259: 257 | B259: 85.781425 | C259: =LN(B259/B7) -> 0.083518273
A260: 258 | B260: 85.876587 | C260: =LN(B260/B8) -> 0.099616412
A261: 259 | B261: 84.587746 | C261: =LN(B261/B9) -> 0.066925517
A262: 260 | B262: 85.392197 | C262: =LN(B262/B10) -> 0.061965365
A263: 261 | B263: 85.668999 | C263: =LN(B263/B11) -> 0.080452014
A264: 262 | B264: 86.992432 | C264: =LN(B264/B12) -> 0.064610463
A265: 263 | B265: 86.706978 | C265: =LN(B265/B13) -> 0.026063305
... A1258: 1256 | B1258: 175.29042 | C1258: =LN(B1258/B1006) -> 0.10099448

Sheet ASUR
B1: ALSEA | C1: ASURB_r | E1: Rendimiento | F1: =AVERAGE(C:C) -> 0.18571237
A2: 0 | B2: 17.997326 | E2: Varianza | F2: =_xlfn.VAR.S(C:C) -> 0.12032069
A3: 1 | B3: 17.559082 | E3: Volatilidad | F3: =SQRT(F2) -> 0.34687273
A4: 2 | B4: 18.474529
A5: 3 | B5: 18.659567
A6: 4 | B6: 18.416096
A7: 5 | B7: 18.260275
A8: 6 | B8: 18.669306
A9: 7 | B9: 19.36076
A10: 8 | B10: 20.393076
A11: 9 | B11: 21.181919
A12: 10 | B12: 23.295242
A13: 11 | B13: 24.639196
A14: 12 | B14: 24.561287
A15: 13 | B15: 23.616621
... A253: 251 | B253: 30.706478
A254: 252 | B254: 31.076553 | C254: =LN(B254/B2) -> 0.54623044
A255: 253 | B255: 30.842823 | C255: =LN(B255/B3) -> 0.56333277
A256: 254 | B256: 30.784389 | C256: =LN(B256/B4) -> 0.51061474
A257: 255 | B257: 31.164202 | C257: =LN(B257/B5) -> 0.51291107
A258: 256 | B258: 32.167301 | C258: =LN(B258/B6) -> 0.55772539
A259: 257 | B259: 32.537376 | C259: =LN(B259/B7) -> 0.57766154
A260: 258 | B260: 33.170399 | C260: =LN(B260/B8) -> 0.5747771
A261: 259 | B261: 33.48204 | C261: =LN(B261/B9) -> 0.54776086
A262: 260 | B262: 32.615288 | C262: =LN(B262/B10) -> 0.4695857
A263: 261 | B263: 32.157562 | C263: =LN(B263/B11) -> 0.4174997
A264: 262 | B264: 34.416965 | C264: =LN(B264/B12) -> 0.39030048
A265: 263 | B265: 34.280624 | C265: =LN(B265/B13) -> 0.33024178
... A1258: 1256 | B1258: 46.862888 | C1258: =LN(B1258/B1006) -> -0.4007353

Sheet Calculos
B2: MATRIZ DE VARIANZAS Y COVARIANZAS (Extendida) | K2: E(Ri) | O2: Cartera | Q2: W_BIMBO | R2: W_Carso | S2: W_GMex | T2: W_FEMSA | U2: W_ASUR | V2: Varianza | W2: Volatilidad | X2: Rendimiento | Z2: Factor | AB2: Volatiliad | AC2: r_anual | AE2: Sharpe ratio
B3: BIMBO | C3: GrupoCarso | D3: GrupoMexico | E3: FEMSA | F3: ASUR | J3: GrupoModelo | K3: =BIMBO!F1 -> 0.12041976 | O3: 1 | P3: CMR | Q3: {=TRANSPOSE(K13:K17)} -> 0.025682596 | R3: 0.030833677 | S3: 0.22470552 | T3: 0.80657313 | U3: -0.087794927 | V3: {=MMULT(MMULT(TRANSPOSE(K13:K17),B4:F8),K13:K17)} -> 0.0051926475 | W3: =SQRT(V3) -> 0.072060027 | X3: =SUMPRODUCT(K3:K7,K13:K17) -> 0.1761795 | Y3: =X3 -> 0.1761795 | Z3: =(X22-X3)/19 -> 0.00098970354 | AA3: Risk Free | AB3: 0 | AC3: =K25 -> 0.089 | AE3: =(AC4-AC3)/AB4 -> 1.3136615
A4: BIMBO | B4: =_xlfn.VAR.S(BIMBO!C:C) -> 0.086213363 | C4: =B5 -> 0.034064563 | D4: =B6 -> -0.021211202 | E4: =B7 -> 0.012239955 | F4: =B8 -> 0.036198172 | G4: 1 | J4: GrupoCarso | K4: =GrupoCarso!F1 -> 0.23729508 | O4: 2 | Q4: =P27 -> 0.018530799 | R4: =Q27 -> 0.035625913 | S4: =R27 -> 0.21858531 | T4: =S27 -> 0.81445636 | U4: =T27 -> -0.087198385 | V4: {=MMULT(MMULT(Q4:U4, $B$4:$F$8), TRANSPOSE(Q4:U4))} -> 0.0051962938 | W4: =SQRT(V4) -> 0.072085323 | X4: {=SUMPRODUCT($K$3:$K$7, TRANSPOSE(Q4:U4))} -> 0.1771692 | Y4: =Y3+$Z$3 -> 0.1771692 | AA4: Portafolio | AB4: =W22 -> 0.080678214 | AC4: =X22 -> 0.19498386
A5: GrupoCarso | B5: =COVAR(BIMBO!C:C,GrupoCarso!C:C) -> 0.034064563 | C5: =_xlfn.VAR.S(GrupoCarso!C:C) -> 0.072253923 | D5: =C6 -> -0.00041566039 | E5: =C7 -> 0.010088729 | F5: =C8 -> 0.067816785 | G5: 1 | J5: GrupoMexico | K5: =GrupoMexico!F1 -> 0.14147764 | O5: 3 | Q5: =P28 -> 0.011379001 | R5: =Q28 -> 0.040418149 | S5: =R28 -> 0.2124651 | T5: =S28 -> 0.8223396 | U5: =T28 -> -0.086601842 | V5: {=MMULT(MMULT(Q5:U5, $B$4:$F$8), TRANSPOSE(Q5:U5))} -> 0.0052072328 | W5: =SQRT(V5) -> 0.072161159 | X5: {=SUMPRODUCT($K$3:$K$7, TRANSPOSE(Q5:U5))} -> 0.1781589 | Y5: =Y4+$Z$3 -> 0.1781589
A6: GrupoMexico | B6: =COVAR(GrupoMexico!C:C,BIMBO!C:C) -> -0.021211202 | C6: =COVAR(GrupoMexico!C:C,GrupoCarso!C:C) -> -0.00041566039 | D6: =_xlfn.VAR.S(GrupoMexico!C:C) -> 0.044911725 | E6: =D7 -> -0.0024086595 | F6: =D8 -> 0.027324246 | G6: 1 | J6: FEMSA | K6: =FEMSA!F1 -> 0.18632399 | O6: 4 | Q6: =P29 -> 0.0042272035 | R6: =Q29 -> 0.045210385 | S6: =R29 -> 0.20634488 | T6: =S29 -> 0.83022283 | U6: =T29 -> -0.0860053 | V6: {=MMULT(MMULT(Q6:U6, $B$4:$F$8), TRANSPOSE(Q6:U6))} -> 0.0052254645 | W6: =SQRT(V6) -> 0.072287374 | X6: {=SUMPRODUCT($K$3:$K$7, TRANSPOSE(Q6:U6))} -> 0.17914861 | Y6: =Y5+$Z$3 -> 0.17914861 | AB6: Volatiliad | AC6: rdiario
A7: FEMSA | B7: =COVAR(FEMSA!C:C,BIMBO!C:C) -> 0.012239955 | C7: =COVAR(FEMSA!C:C,GrupoCarso!C:C) -> 0.010088729 | D7: =COVAR(FEMSA!C:C,GrupoMexico!C:C) -> -0.0024086595 | E7: =_xlfn.VAR.S(FEMSA!C:C) -> 0.0072236284 | F7: =E8 -> 0.0081772883 | G7: 1 | J7: ASUR | K7: =ASUR!F1 -> 0.18571237 | O7: 5 | Q7: =P30 -> -0.0029245941 | R7: =Q30 -> 0.050002621 | S7: =R30 -> 0.20022467 | T7: =S30 -> 0.83810606 | U7: =T30 -> -0.085408758 | V7: {=MMULT(MMULT(Q7:U7, $B$4:$F$8), TRANSPOSE(Q7:U7))} -> 0.0052509888 | W7: =SQRT(V7) -> 0.072463707 | X7: {=SUMPRODUCT($K$3:$K$7, TRANSPOSE(Q7:U7))} -> 0.18013831 | Y7: =Y6+$Z$3 -> 0.18013831 | AB7: 0.01795939 | AC7: =X22 -> 0.19498386
A8: ASUR | B8: =COVAR(ASUR!C:C,BIMBO!C:C) -> 0.036198172 | C8: =COVAR(ASUR!C:C,GrupoCarso!C:C) -> 0.067816785 | D8: =COVAR(ASUR!C:C,GrupoMexico!C:C) -> 0.027324246 | E8: =COVAR(ASUR!C:C,FEMSA!C:C) -> 0.0081772883 | F8: =_xlfn.VAR.S(ASUR!C:C) -> 0.12032069 | G8: 1 | O8: 6 | Q8: =P31 -> -0.010076392 | R8: =Q31 -> 0.054794857 | S8: =R31 -> 0.19410446 | T8: =S31 -> 0.84598929 | U8: =T31 -> -0.084812216 | V8: {=MMULT(MMULT(Q8:U8, $B$4:$F$8), TRANSPOSE(Q8:U8))} -> 0.0052838058 | W8: =SQRT(V8) -> 0.072689792 | X8: {=SUMPRODUCT($K$3:$K$7, TRANSPOSE(Q8:U8))} -> 0.18112801 | Y8: =Y7+$Z$3 -> 0.18112801 | AB8: 0.02 | AC8: =K26*(AB8-AB7)+AC7 -> 0.19498434
B9: 1 | C9: 1 | D9: 1 | E9: 1 | F9: 1 | G9: 0 | O9: 7 | Q9: =P32 -> -0.017228189 | R9: =Q32 -> 0.059587093 | S9: =R32 -> 0.18798425 | T9: =S32 -> 0.85387252 | U9: =T32 -> -0.084215674 | V9: {=MMULT(MMULT(Q9:U9, $B$4:$F$8), TRANSPOSE(Q9:U9))} -> 0.0053239155 | W9: =SQRT(V9) -> 0.072965166 | X9: {=SUMPRODUCT($K$3:$K$7, TRANSPOSE(Q9:U9))} -> 0.18211772 | Y9: =Y8+$Z$3 -> 0.18211772
O10: 8 | Q10: =P33 -> -0.024379987 | R10: =Q33 -> 0.064379329 | S10: =R33 -> 0.18186403 | T10: =S33 -> 0.86175576 | U10: =T33 -> -0.083619132 | V10: {=MMULT(MMULT(Q10:U10, $B$4:$F$8), TRANSPOSE(Q10:U10))} -> 0.0053713178 | W10: =SQRT(V10) -> 0.073289275 | X10: {=SUMPRODUCT($K$3:$K$7, TRANSPOSE(Q10:U10))} -> 0.18310742 | Y10: =Y9+$Z$3 -> 0.18310742
O11: 9 | Q11: =P34 -> -0.031531785 | R11: =Q34 -> 0.069171565 | S11: =R34 -> 0.17574382 | T11: =S34 -> 0.86963899 | U11: =T34 -> -0.083022589 | V11: {=MMULT(MMULT(Q11:U11, $B$4:$F$8), TRANSPOSE(Q11:U11))} -> 0.0054260129 | W11: =SQRT(V11) -> 0.073661475 | X11: {=SUMPRODUCT($K$3:$K$7, TRANSPOSE(Q11:U11))} -> 0.18409712 | Y11: =Y10+$Z$3 -> 0.18409712
B12: Matriz inversa (extendida) | I12: Vec Aux | K12: wi (minima varianza) | O12: 10 | Q12: =P35 -> -0.038683582 | R12: =Q35 -> 0.073963801 | S12: =R35 -> 0.16962361 | T12: =S35 -> 0.87752222 | U12: =T35 -> -0.082426047 | V12: {=MMULT(MMULT(Q12:U12, $B$4:$F$8), TRANSPOSE(Q12:U12))} -> 0.0054880005 | W12: =SQRT(V12) -> 0.07408104 | X12: {=SUMPRODUCT($K$3:$K$7, TRANSPOSE(Q12:U12))} -> 0.18508683 | Y12: =Y11+$Z$3 -> 0.18508683
B13: {=MINVERSE(B4:G9)} -> 21.687609 | C13: 1.8340654 | D13: 13.620368 | E13: -28.193145 | F13: -8.9488984 | G13: 0.025682596 | I13: 0 | K13: {=MMULT(B13:G18,I13:I18)} -> 0.025682596 | O13: 11 | Q13: =P36 -> -0.04583538 | R13: =Q36 -> 0.078756037 | S13: =R36 -> 0.1635034 | T13: =S36 -> 0.88540545 | U13: =T36 -> -0.081829505 | V13: {=MMULT(MMULT(Q13:U13, $B$4:$F$8), TRANSPOSE(Q13:U13))} -> 0.0055572809 | W13: =SQRT(V13) -> 0.074547172 | X13: {=SUMPRODUCT($K$3:$K$7, TRANSPOSE(Q13:U13))} -> 0.18607653 | Y13: =Y12+$Z$3 -> 0.18607653
B14: 1.8340654 | C14: 39.501337 | D14: 13.524716 | E14: -30.81035 | F14: -24.049767 | G14: 0.030833677 | I14: 0 | K14: 0.030833677 | O14: 12 | Q14: =P37 -> -0.052987177 | R14: =Q37 -> 0.083548273 | S14: =R37 -> 0.15738318 | T14: =S37 -> 0.89328868 | U14: =T37 -> -0.081232963 | V14: {=MMULT(MMULT(Q14:U14, $B$4:$F$8), TRANSPOSE(Q14:U14))} -> 0.0056338539 | W14: =SQRT(V14) -> 0.075059003 | X14: {=SUMPRODUCT($K$3:$K$7, TRANSPOSE(Q14:U14))} -> 0.18706623 | Y14: =Y13+$Z$3 -> 0.18706623
B15: 13.620368 | C15: 13.524716 | D15: 32.645224 | E15: -41.616932 | F15: -18.173376 | G15: 0.22470552 | I15: 0 | K15: 0.22470552 | O15: 13 | Q15: =P38 -> -0.060138975 | R15: =Q38 -> 0.088340509 | S15: =R38 -> 0.15126297 | T15: =S38 -> 0.90117192 | U15: =T38 -> -0.080636421 | V15: {=MMULT(MMULT(Q15:U15, $B$4:$F$8), TRANSPOSE(Q15:U15))} -> 0.0057177196 | W15: =SQRT(V15) -> 0.075615604 | X15: {=SUMPRODUCT($K$3:$K$7, TRANSPOSE(Q15:U15))} -> 0.18805594 | Y15: =Y14+$Z$3 -> 0.18805594
B16: -28.193145 | C16: -30.81035 | D16: -41.616932 | E16: 77.277323 | F16: 23.343104 | G16: 0.80657313 | I16: 0 | K16: 0.80657313 | O16: 14 | Q16: =P39 -> -0.067290772 | R16: =Q39 -> 0.093132745 | S16: =R39 -> 0.14514276 | T16: =S39 -> 0.90905515 | U16: =T39 -> -0.080039879 | V16: {=MMULT(MMULT(Q16:U16, $B$4:$F$8), TRANSPOSE(Q16:U16))} -> 0.005808878 | W16: =SQRT(V16) -> 0.076215995 | X16: {=SUMPRODUCT($K$3:$K$7, TRANSPOSE(Q16:U16))} -> 0.18904564 | Y16: =Y15+$Z$3 -> 0.18904564
B17: -8.9488984 | C17: -24.049767 | D17: -18.173376 | E17: 23.343104 | F17: 27.828938 | G17: -0.087794927 | I17: 0 | K17: -0.087794927 | O17: 15 | Q17: =P40 -> -0.07444257 | R17: =Q40 -> 0.097924981 | S17: =R40 -> 0.13902255 | T17: =S40 -> 0.91693838 | U17: =T40 -> -0.079443336 | V17: {=MMULT(MMULT(Q17:U17, $B$4:$F$8), TRANSPOSE(Q17:U17))} -> 0.005907329 | W17: =SQRT(V17) -> 0.07685915 | X17: {=SUMPRODUCT($K$3:$K$7, TRANSPOSE(Q17:U17))} -> 0.19003534 | Y17: =Y16+$Z$3 -> 0.19003534
B18: 0.025682596 | C18: 0.030833677 | D18: 0.22470552 | E18: 0.80657313 | F18: -0.087794927 | G18: -0.0051926475 | I18: 1 | K18: -0.0051926475 | O18: 16 | Q18: =P41 -> -0.081594368 | R18: =Q41 -> 0.10271722 | S18: =R41 -> 0.13290233 | T18: =S41 -> 0.92482161 | U18: =T41 -> -0.078846794 | V18: {=MMULT(MMULT(Q18:U18, $B$4:$F$8), TRANSPOSE(Q18:U18))} -> 0.0060130727 | W18: =SQRT(V18) -> 0.077544005 | X18: {=SUMPRODUCT($K$3:$K$7, TRANSPOSE(Q18:U18))} -> 0.19102505 | Y18: =Y17+$Z$3 -> 0.19102505
O19: 17 | Q19: =P42 -> -0.088746165 | R19: =Q42 -> 0.10750945 | S19: =R42 -> 0.12678212 | T19: =S42 -> 0.93270484 | U19: =T42 -> -0.078250252 | V19: {=MMULT(MMULT(Q19:U19, $B$4:$F$8), TRANSPOSE(Q19:U19))} -> 0.0061261091 | W19: =SQRT(V19) -> 0.078269464 | X19: {=SUMPRODUCT($K$3:$K$7, TRANSPOSE(Q19:U19))} -> 0.19201475 | Y19: =Y18+$Z$3 -> 0.19201475
O20: 18 | Q20: =P43 -> -0.095897963 | R20: =Q43 -> 0.11230169 | S20: =R43 -> 0.12066191 | T20: =S43 -> 0.94058808 | U20: =T43 -> -0.07765371 | V20: {=MMULT(MMULT(Q20:U20, $B$4:$F$8), TRANSPOSE(Q20:U20))} -> 0.0062464381 | W20: =SQRT(V20) -> 0.079034411 | X20: {=SUMPRODUCT($K$3:$K$7, TRANSPOSE(Q20:U20))} -> 0.19300446 | Y20: =Y19+$Z$3 -> 0.19300446
O21: 19 | Q21: =P44 -> -0.10304976 | R21: =Q44 -> 0.11709392 | S21: =R44 -> 0.1145417 | T21: =S44 -> 0.94847131 | U21: =T44 -> -0.077057168 | V21: {=MMULT(MMULT(Q21:U21, $B$4:$F$8), TRANSPOSE(Q21:U21))} -> 0.0063740598 | W21: =SQRT(V21) -> 0.079837709 | X21: {=SUMPRODUCT($K$3:$K$7, TRANSPOSE(Q21:U21))} -> 0.19399416 | Y21: =Y20+$Z$3 -> 0.19399416
B22: MATRIZ AUXILIAR | O22: 20 | P22: CM | Q22: {=TRANSPOSE(L32:L36)} -> -0.11020156 | R22: 0.12188616 | S22: 0.10842148 | T22: 0.95635454 | U22: -0.076460626 | V22: {=MMULT(MMULT(TRANSPOSE(L32:L36),B4:F8),L32:L36)} -> 0.0065089742 | W22: =SQRT(V22) -> 0.080678214 | X22: {=SUMPRODUCT($K$3:$K$7, TRANSPOSE(Q22:U22))} -> 0.19498386 | Y22: =Y21+$Z$3 -> 0.19498386
B23: =_xlfn.VAR.S(BIMBO!C:C) -> 0.086213363 | C23: =B24 -> 0.034064563 | D23: =B25 -> -0.021211202 | E23: =B26 -> 0.012239955 | F23: =B27 -> 0.036198172 | G23: 1 | H23: {=TRANSPOSE(B29:F29)} -> 0.12041976 | J23: Rf | K23: =0.102 -> 0.102
B24: =COVAR(BIMBO!C:C,GrupoCarso!C:C) -> 0.034064563 | C24: =_xlfn.VAR.S(GrupoCarso!C:C) -> 0.072253923 | D24: =C25 -> -0.00041566039 | E24: =C26 -> 0.010088729 | F24: =C27 -> 0.067816785 | G24: 1 | H24: 0.23729508 | J24: Rf diaria | K24: =K23/360 -> 0.00028333333
B25: =COVAR(GrupoMexico!C:C,BIMBO!C:C) -> -0.021211202 | C25: =COVAR(GrupoMexico!C:C,GrupoCarso!C:C) -> -0.00041566039 | D25: =_xlfn.VAR.S(GrupoMexico!C:C) -> 0.044911725 | E25: =D26 -> -0.0024086595 | F25: =D27 -> 0.027324246 | G25: 1 | H25: 0.14147764 | J25: Préstamo anual | K25: 0.089
B26: =COVAR(FEMSA!C:C,BIMBO!C:C) -> 0.012239955 | C26: =COVAR(FEMSA!C:C,GrupoCarso!C:C) -> 0.010088729 | D26: =COVAR(FEMSA!C:C,GrupoMexico!C:C) -> -0.0024086595 | E26: =_xlfn.VAR.S(FEMSA!C:C) -> 0.0072236284 | F26: =E27 -> 0.0081772883 | G26: 1 | H26: 0.18632399 | J26: Préstamo diario | K26: =(1+K25)^(1/365)-1 -> 0.0002336159 | P26: BIMBO | Q26: GrupoCarso | R26: GrupoMexico | S26: FEMSA | T26: ASUR
B27: =COVAR(ASUR!C:C,BIMBO!C:C) -> 0.036198172 | C27: =COVAR(ASUR!C:C,GrupoCarso!C:C) -> 0.067816785 | D27: =COVAR(ASUR!C:C,GrupoMexico!C:C) -> 0.027324246 | E27: =COVAR(ASUR!C:C,FEMSA!C:C) -> 0.0081772883 | F27: =_xlfn.VAR.S(ASUR!C:C) -> 0.12032069 | G27: 1 | H27: 0.18571237 | J27: https://www.yotepresto.com/prestamos-personales?utm_source=googleads&utm_medium=g&utm_content=79605897483:626835688024&utm_campaign=6944045184&utm_term=kwd-14280251&keyword=prestamos&adposition=&gad_source=1&gbraid=0AAAAADcws_xJ-xHGQD9lS5VKXullXyWSy&gclid=Cj0KCQiA88a5BhDPARIsAFj595iRg0Cm058UDves8XV4Z5H1MgPcfJWBM40iceRNkh_Mzv95fgJbtvkaApyTEALw_wcB#simulator | P27: {=TRANSPOSE(MMULT($B$41:$H$47,B51:B57))} -> 0.018530799 | Q27: 0.035625913 | R27: 0.21858531 | S27: 0.81445636 | T27: -0.087198385 | U27: -0.0045435548 | V27: -0.0036842693 | W27: =SUM(P27:T27) -> 1
B28: 1 | C28: 1 | D28: 1 | E28: 1 | F28: 1 | G28: 0 | H28: 0 | P28: {=TRANSPOSE(MMULT($B$41:$H$47,C51:C57))} -> 0.011379001 | Q28: 0.040418149 | R28: 0.2124651 | S28: 0.8223396 | T28: -0.086601842 | U28: -0.0038944621 | V28: -0.0073685385 | W28: =SUM(P28:T28) -> 1
B29: {=TRANSPOSE(K3:K7)} -> 0.12041976 | C29: 0.23729508 | D29: 0.14147764 | E29: 0.18632399 | F29: 0.18571237 | G29: 0 | H29: 0 | P29: {=TRANSPOSE(MMULT($B$41:$H$47,D51:D57))} -> 0.0042272035 | Q29: 0.045210385 | R29: 0.20634488 | S29: 0.83022283 | T29: -0.0860053 | U29: -0.0032453694 | V29: -0.011052808 | W29: =SUM(P29:T29) -> 1
P30: {=TRANSPOSE(MMULT($B$41:$H$47,E51:E57))} -> -0.0029245941 | Q30: 0.050002621 | R30: 0.20022467 | S30: 0.83810606 | T30: -0.085408758 | U30: -0.0025962767 | V30: -0.014737077 | W30: =SUM(P30:T30) -> 1
B31: Matriz Inversa | H31: E(Ri) - rf | J31: Ui | L31: wi (de mercado) | P31: {=TRANSPOSE(MMULT($B$41:$H$47,F51:F57))} -> -0.010076392 | Q31: 0.054794857 | R31: 0.19410446 | S31: 0.84598929 | T31: -0.084812216 | U31: -0.001947184 | V31: -0.018421346 | W31: =SUM(P31:T31) -> 1
B32: {=MINVERSE(B23:F27)} -> 21.814634 | C32: 1.9865673 | D32: 14.731751 | E32: -24.203871 | F32: -9.3831281 | H32: =K3-$K$23 -> 0.018419758 | J32: {=MMULT(B32:F36,H32:H36)} -> -1.5742829 | L32: =J32/$J$37 -> -0.11020156 | P32: {=TRANSPOSE(MMULT($B$41:$H$47,G51:G57))} -> -0.017228189 | Q32: 0.059587093 | R32: 0.18798425 | S32: 0.85387252 | T32: -0.084215674 | U32: -0.0012980913 | V32: -0.022105616 | W32: =SUM(P32:T32) -> 1
B33: 1.9865673 | C33: 39.684425 | D33: 14.859006 | E33: -26.02096 | F33: -24.571089 | H33: =K4-$K$23 -> 0.13529508 | J33: 1.7412031 | L33: =J33/$J$37 -> 0.12188616 | P33: {=TRANSPOSE(MMULT($B$41:$H$47,H51:H57))} -> -0.024379987 | Q33: 0.064379329 | R33: 0.18186403 | S33: 0.86175576 | T33: -0.083619132 | U33: -0.00064899856 | V33: -0.025789885 | W33: =SUM(P33:T33) -> 1
B34: 14.731751 | C34: 14.859006 | D34: 42.369083 | E34: -6.7134574 | F34: -21.972595 | H34: =K5-$K$23 -> 0.039477639 | J34: 1.5488536 | L34: =J34/$J$37 -> 0.10842148 | P34: {=TRANSPOSE(MMULT($B$41:$H$47,I51:I57))} -> -0.031531785 | Q34: 0.069171565 | R34: 0.17574382 | S34: 0.86963899 | T34: -0.083022589 | U34: 9.414194e-08 | V34: -0.029474154 | W34: =SUM(P34:T34) -> 1 | AB34: FIGURA 2.1
B35: -24.203871 | C35: -26.02096 | D35: -6.7134574 | E35: 202.5622 | F35: 9.705931 | H35: =K6-$K$23 -> 0.084323985 | J35: 13.66199 | L35: =J35/$J$37 -> 0.95635454 | P35: {=TRANSPOSE(MMULT($B$41:$H$47,J51:J57))} -> -0.038683582 | Q35: 0.073963801 | R35: 0.16962361 | S35: 0.87752222 | T35: -0.082426047 | U35: 0.00064918684 | V35: -0.033158423 | W35: =SUM(P35:T35) -> 1
B36: -9.3831281 | C36: -24.571089 | D36: -21.972595 | E36: 9.705931 | F36: 29.313335 | H36: =K7-$K$23 -> 0.083712367 | J36: -1.0922772 | L36: =J36/$J$37 -> -0.076460626 | P36: {=TRANSPOSE(MMULT($B$41:$H$47,K51:K57))} -> -0.04583538 | Q36: 0.078756037 | R36: 0.1635034 | S36: 0.88540545 | T36: -0.081829505 | U36: 0.0012982795 | V36: -0.036842693 | W36: =SUM(P36:T36) -> 1
J37: =SUM(J32:J36) -> 14.285486 | P37: {=TRANSPOSE(MMULT($B$41:$H$47,L51:L57))} -> -0.052987177 | Q37: 0.083548273 | R37: 0.15738318 | S37: 0.89328868 | T37: -0.081232963 | U37: 0.0019473722 | V37: -0.040526962 | W37: =SUM(P37:T37) -> 1
P38: {=TRANSPOSE(MMULT($B$41:$H$47,M51:M57))} -> -0.060138975 | Q38: 0.088340509 | R38: 0.15126297 | S38: 0.90117192 | T38: -0.080636421 | U38: 0.0025964649 | V38: -0.044211231 | W38: =SUM(P38:T38) -> 1
P39: {=TRANSPOSE(MMULT($B$41:$H$47,N51:N57))} -> -0.067290772 | Q39: 0.093132745 | R39: 0.14514276 | S39: 0.90905515 | T39: -0.080039879 | U39: 0.0032455576 | V39: -0.047895501 | W39: =SUM(P39:T39) -> 1
B40: MATRIZ AUXILIAR (Inversa) | J40: Vector auxiliar | L40: WFE | P40: {=TRANSPOSE(MMULT($B$41:$H$47,O51:O57))} -> -0.07444257 | Q40: 0.097924981 | R40: 0.13902255 | S40: 0.91693838 | T40: -0.079443336 | U40: 0.0038946503 | V40: -0.05157977 | W40: =SUM(P40:T40) -> 1
B41: {=MINVERSE(B23:H29)} -> 7.660314 | C41: 11.233396 | D41: 1.6163889 | E41: -12.731238 | F41: -7.7788607 | G41: 1.2987912 | H41: -7.2262019 | J41: 0 | L41: {=MMULT(B41:H47,J41:J47)} -> 1.2992698 | P41: {=TRANSPOSE(MMULT($B$41:$H$47,P51:P57))} -> -0.081594368 | Q41: 0.10271722 | R41: 0.13290233 | S41: 0.92482161 | T41: -0.078846794 | U41: 0.004543743 | V41: -0.055264039 | W41: =SUM(P41:T41) -> 1
...

Sheet Hoja 7
E4: PORTAFOLIO DE MINIMA VARIANZA | L4: Portafolio Optimo
B5: Capital | C5: Y | D5: rf | E5: PR | F5: BIMBO | G5: GrupoCarso | H5: GrupoMexico | I5: FEMSA | J5: ASUR | K5: BIMBO | L5: GrupoCarso | M5: GrupoMexico | N5: FEMSA | O5: ASUR | P5: E(RMV) | Q5: Prima de Riesgo
A6: inversor 1 | B6: 50000000 | C6: 0.6 | D6: =C6*B6 -> 30000000 | E6: =B6-D6 -> 20000000 | F6: =Calculos!Q3*E6 -> 513651.92 | G6: =Calculos!R3*E6 -> 616673.54 | H6: =Calculos!S3*E6 -> 4494110.5 | I6: =Calculos!T3*E6 -> 16131463 | J6: =Calculos!U3*E6 -> -1755898.5 | K6: =Calculos!$Q$22*D6 -> -3306046.7 | L6: =Calculos!$R$22*D6 -> 3656584.8 | M6: =Calculos!$S$22*D6 -> 3252644.5 | N6: =Calculos!$T$22*D6 -> 28690636 | O6: =Calculos!$U$22*D6 -> -2293818.8 | P6: =C6*Calculos!X3+(1-C6)*Calculos!K24 -> 0.10582103 | Q6: =P6-Calculos!K24 -> 0.1055377
A7: inversor 2 | B7: 500000 | C7: 0.5 | D7: =C7*B7 -> 250000 | E7: =B7-D7 -> 250000 | F7: =Calculos!Q4*E7 -> 4632.6997 | G7: =Calculos!R4*E7 -> 8906.4782 | H7: =Calculos!S4*E7 -> 54646.328 | I7: =Calculos!T4*E7 -> 203614.09 | J7: =Calculos!U4*E7 -> -21799.596 | K7: =Calculos!$Q$22*D7 -> -27550.39 | L7: =Calculos!$R$22*D7 -> 30471.54 | M7: =Calculos!$S$22*D7 -> 27105.371 | N7: =Calculos!$T$22*D7 -> 239088.64 | O7: =Calculos!$U$22*D7 -> -19115.156 | P7: =C7*Calculos!X4+(1-C7)*Calculos!K25 -> 0.1330846 | Q7: =P7-Calculos!K25 -> 0.044084599
A8: inversor 3 | B8: 700000 | C8: 0.75 | D8: =C8*B8 -> 525000 | E8: =B8-D8 -> 175000 | F8: =Calculos!Q5*E8 -> 1991.3252 | G8: =Calculos!R5*E8 -> 7073.176 | H8: =Calculos!S5*E8 -> 37181.392 | I8: =Calculos!T5*E8 -> 143909.43 | J8: =Calculos!U5*E8 -> -15155.322 | K8: =Calculos!$Q$22*D8 -> -57855.818 | L8: =Calculos!$R$22*D8 -> 63990.234 | M8: =Calculos!$S$22*D8 -> 56921.279 | N8: =Calculos!$T$22*D8 -> 502086.13 | O8: =Calculos!$U$22*D8 -> -40141.828 | P8: =C8*Calculos!X5+(1-C8)*Calculos!K26 -> 0.13367758 | Q8: =P8-Calculos!K26 -> 0.13344396
A9: inversor 4 | B9: 100000 | C9: 1.5 | D9: =C9*B9 -> 150000 | E9: =B9-D9 -> -50000 | F9: =Calculos!Q6*E9 -> -211.36017 | G9: =Calculos!R6*E9 -> -2260.5192 | H9: =Calculos!S6*E9 -> -10317.244 | I9: =Calculos!T6*E9 -> -41511.141 | J9: =Calculos!U6*E9 -> 4300.265 | K9: =Calculos!$Q$22*D9 -> -16530.234 | L9: =Calculos!$R$22*D9 -> 18282.924 | M9: =Calculos!$S$22*D9 -> 16263.222 | N9: =Calculos!$T$22*D9 -> 143453.18 | O9: =Calculos!$U$22*D9 -> -11469.094 | P9: =C9*Calculos!X6+(1-C9)*Calculos!K27 -> 0.26872291 | Q9: =P9-Calculos!K27 -> 0.26872291
E12: PORTAFOLIO DE MINIMA VARIANZA | L12: Portafolio Optimo
B13: Capital | C13: Y | D13: rf | E13: PR | F13: BIMBO | G13: GrupoCarso | H13: GrupoMexico | I13: FEMSA | J13: ASUR | K13: Bimbo | L13: GrupoCarso | M13: GrupoMexico | N13: FEMSA | O13: ASUR | P13: E(RMV) | Q13: Prima de Riesgo
A14: inversor 1 | B14: 50000000 | C14: 0.4 | D14: =C14*B14 -> 20000000 | E14: =B14-D14 -> 30000000 | F14: =Calculos!Q11*E14 -> -945953.54 | G14: =Calculos!R11*E14 -> 2075146.9 | H14: =Calculos!S11*E14 -> 5272314.7 | I14: =Calculos!T11*E14 -> 26089170 | J14: =Calculos!U11*E14 -> -2490677.7 | K14: =Calculos!$Q$22*D14 -> -2204031.2 | L14: =Calculos!$R$22*D14 -> 2437723.2 | M14: =Calculos!$S$22*D14 -> 2168429.7 | N14: =Calculos!$T$22*D14 -> 19127091 | O14: =Calculos!$U$22*D14 -> -1529212.5 | P14: =C14*Calculos!X11+(1-C14)*Calculos!K32 -> 0.073638849 | Q14: =P14-Calculos!K32 -> 0.073638849
A15: inversor 2 | B15: 500000 | C15: 0.6 | D15: =C15*B15 -> 300000 | E15: =B15-D15 -> 200000 | F15: =Calculos!Q12*E15 -> -7736.7164 | G15: =Calculos!R12*E15 -> 14792.76 | H15: =Calculos!S12*E15 -> 33924.722 | I15: =Calculos!T12*E15 -> 175504.44 | J15: =Calculos!U12*E15 -> -16485.209 | K15: =Calculos!$Q$22*D15 -> -33060.467 | L15: =Calculos!$R$22*D15 -> 36565.848 | M15: =Calculos!$S$22*D15 -> 32526.445 | N15: =Calculos!$T$22*D15 -> 286906.36 | O15: =Calculos!$U$22*D15 -> -22938.188 | P15: =C15*Calculos!X12+(1-C15)*Calculos!K33 -> 0.1110521 | Q15: =P15-Calculos!K33 -> 0.1110521
A16: inversor 3 | B16: 700000 | C16: 1.2 | D16: =C16*B16 -> 840000 | E16: =B16-D16 -> -140000 | F16: =Calculos!Q13*E16 -> 6416.9532 | G16: =Calculos!R13*E16 -> -11025.845 | H16: =Calculos!S13*E16 -> -22890.476 | I16: =Calculos!T13*E16 -> -123956.76 | J16: =Calculos!U13*E16 -> 11456.131 | K16: =Calculos!$Q$22*D16 -> -92569.309 | L16: =Calculos!$R$22*D16 -> 102384.37 | M16: =Calculos!$S$22*D16 -> 91074.046 | N16: =Calculos!$T$22*D16 -> 803337.81 | O16: =Calculos!$U$22*D16 -> -64226.926 | P16: =C16*Calculos!X13+(1-C16)*Calculos!K34 -> 0.22329184 | Q16: =P16-Calculos!K34 -> 0.22329184
A17: inversor 4 | B17: 100000 | C17: 0.9 | D17: =C17*B17 -> 90000 | E17: =B17-D17 -> 10000 | F17: =Calculos!Q14*E17 -> -529.87177 | G17: =Calculos!R14*E17 -> 835.48273 | H17: =Calculos!S14*E17 -> 1573.8318 | I17: =Calculos!T14*E17 -> 8932.8868 | J17: =Calculos!U14*E17 -> -812.32963 | K17: =Calculos!$Q$22*D17 -> -9918.1402 | L17: =Calculos!$R$22*D17 -> 10969.754 | M17: =Calculos!$S$22*D17 -> 9757.9335 | N17: =Calculos!$T$22*D17 -> 86071.909 | O17: =Calculos!$U$22*D17 -> -6881.4563 | P17: =C17*Calculos!X14+(1-C17)*Calculos!K35 -> 0.16835961 | Q17: =P17-Calculos!K35 -> 0.16835961
F19: =F6-F14 -> 1459605.5 | G19: =G6-G14 -> -1458473.4 | H19: =H6-H14 -> -778204.2 | I19: =I6-I14 -> -9957707 | J19: =J6-J14 -> 734779.15 | K19: =K6-K14 -> -1102015.6 | L19: =L6-L14 -> 1218861.6 | M19: =M6-M14 -> 1084214.8 | ... O19: =O6-O14 -> -764606.26
F20: =F7-F15 -> 12369.416 | G20: =G7-G15 -> -5886.2819 | H20: =H7-H15 -> 20721.606 | I20: =I7-I15 -> 28109.647 | J20: =J7-J15 -> -5314.3867 | K20: =K7-K15 -> 5510.0779 | L20: =L7-L15 -> -6094.308 | M20: =M7-M15 -> -5421.0741 | ... O20: =O7-O15 -> 3823.0313
F21: =F8-F16 -> -4425.628 | G21: =G8-G16 -> 18099.021 | H21: =H8-H16 -> 60071.868 | I21: =I8-I16 -> 267866.19 | J21: =J8-J16 -> -26611.453 | K21: =K8-K16 -> 34713.491 | L21: =L8-L16 -> -38394.141 | M21: =M8-M16 -> -34152.767 | ... O21: =O8-O16 -> 24085.097
F22: =F9-F17 -> 318.5116 | G22: =G9-G17 -> -3096.002 | H22: =H9-H17 -> -11891.076 | I22: =I9-I17 -> -50444.028 | J22: =J9-J17 -> 5112.5946 | K22: =K9-K17 -> -6612.0935 | L22: =L9-L17 -> 7313.1696 | M22: =M9-M17 -> 6505.289 | ... O22: =O9-O17 -> -4587.6375
